Workbook
Name Slicer_Department_Name: #N/A
Name Slicer_Employment_Status2: #N/A
Name Slicer_Year_of_Service: #N/A

Sheet Raw_Employee_Data
A1: Emp ID | B1: First_Name | C1: Last_Name | D1: Dept Code | E1: Hire Date | F1: Salary | G1: Perf_Score | H1: Employment Status
A2: EMP127 | B2: Emily | C2: Brown | D2: IT02 | E2: 43093 | F2: 50361 | G2: 52 | H2: active
A3: EMP046 | B3: Richard | C3: Hernandez | D3: MKT04 | E3: 44659 | F3: 112673 | H3: ACTIVE
A4: EMP134 | B4: Emily | C4: Gonzalez | D4: IT02 | E4: 42431 | F4: $114,425 | G4: 54 | H4: LEFT
A5: EMP139 | B5: John | C5: Martinez | D5: FIN03 | E5: 45110 | F5: 103831 | G5: 70 | H5: active
A6: EMP112 | B6: Thomas | C6: Smith | D6: IT02 | E6: 44977 | F6: 73785 | G6: 40 | H6: Left
A7: EMP030 | B7: Emily | C7: Johnson | D7: OPS06 | E7: 02-Mar-20 | F7: 115882 | G7: 49 | H7: ACTIVE
A8: EMP096 | B8: John | C8: Wilson | D8: OPS06 | E8: 45272 | F8: 59980 | G8: 70 | H8: Left
A9: EMP098 | B9: Jessica | C9: Smith | D9: OPS06 | E9: 44174 | F9: 68728 | G9: 45 | H9: ACTIVE
A10: EMP095 | C10: Rodriguez | D10: FIN03 | E10: 43107 | F10: 102139 | G10: 79 | H10: active
A11: EMP140 | B11: Michael | C11: Martinez | D11: SAL05 | E11: 42676 | F11: 94998 | G11: 58 | H11: Active
A12: EMP020 | B12: Emily | C12: Miller | D12: sal05 | E12: 43911 | F12: $118,635 | G12: 49 | H12: Active
A13: EMP057 | B13: Emily | C13: Hernandez | D13: IT02 | E13: 42425 | F13: 76918 | G13: 62 | H13: Actv
A14: EMP016 | B14: Jane | C14: Williams | D14: mkt04 | E14: 17-Jun-21 | F14: 61408 | G14: 48 | H14: ACTIVE
A15: EMP070 | B15: Jane | C15: Miller | D15: MKT04 | E15: 44001 | F15: 99990 | G15: 54 | H15: Actv
A16: EMP025 | B16: Robert | C16: Jones | D16: MKT04 | E16: 43820 | F16: 80385 | H16: active
A17: EMP031 | B17: Thomas | C17: Rodriguez | D17: SAL05 | E17: 45169 | F17: 65290 | G17: 77 | H17: active
A18: EMP126 | B18: Emily | C18: Davis | D18: IT02 | E18: 42337 | F18: 105765 | G18: 42 | H18: Active
A19: EMP109 | B19: James | C19: Martinez | D19: SAL05 | E19: 42899 | F19: 102921 | G19: 49 | H19: ACTIVE
A20: EMP057 | B20: Emily | C20: Hernandez | D20: IT02 | E20: 42425 | F20: 76918 | G20: 62 | H20: Actv
A21: EMP066 | B21: Ashley | C21: Lopez | D21: MKT04 | E21: 43235 | F21: 73984 | G21: 93 | H21: Actv
A22: EMP120 | B22: Amanda | C22: Gonzalez | D22: IT02 | E22: 42575 | G22: 75 | H22: Actv
A23: EMP019 | B23: Michael | C23: Hernandez | D23: FIN03 | E23: 43076 | F23: 118527 | G23: 50 | H23: Actv
A24: EMP013 | B24: Richard | C24: Hernandez | D24: MKT04 | E24: 44353 | F24: 107871 | G24: 88 | H24: active
A25: EMP010 | B25: Michael | C25: Rodriguez | D25: IT02 | E25: 44815 | F25: 93956 | G25: 50 | H25: LEFT
A26: EMP032 | B26: Jessica | C26: Johnson | D26: FIN03 | E26: 42565 | F26: 100851 | G26: 64 | H26: ACTIVE
A27: EMP082 | B27: Ashley | C27: Williams | D27: SAL05 | E27: 44728 | F27: 68655 | G27: 32 | H27: active
A28: EMP052 | C28: Williams | D28: SAL05 | E28: 45134 | F28: 81205 | G28: 59 | H28: Actv
A29: EMP129 | B29: John | C29: Wilson | D29: SAL05 | E29: 09/24/2019 | F29: $77,610 | G29: 88 | H29: Actv
A30: EMP146 | B30: Thomas | C30: Rodriguez | D30: it02 | E30: 44765 | F30: $50,873 | G30: 90 | H30: Active
A31: EMP099 | B31: Michael | C31: Wilson | D31: fin03 | E31: 13-May-18 | F31: 85312 | G31: 66 | H31: active
A32: EMP015 | B32: John | C32: Rodriguez | D32: SAL05 | E32: 42202 | G32: 68 | H32: active
A33: EMP076 | B33: Thomas | C33: Hernandez | D33: OPS06 | E33: 05-Aug-15 | F33: 97055 | G33: 80 | H33: Actv
A34: EMP137 | B34: Michael | C34: Johnson | D34: IT02 | E34: 45195 | F34: 66069 | G34: 72 | H34: Actv
A35: EMP056 | B35: Sarah | C35: Brown | D35: it02 | E35: 10-Jun-19 | F35: 90157 | G35: 58 | H35: active
A36: EMP125 | B36: Jane | C36: Martinez | D36: HR01 | E36: 44578 | F36: 59899 | G36: 78 | H36: Actv
A37: EMP085 | B37: Emily | C37: Jones | D37: FIN03 | E37: 03-Jul-17 | F37: 113389 | G37: 30 | H37: ACTIVE
A38: EMP106 | C38: Brown | D38: IT02 | E38: 01-Sep-15 | F38: 102691 | G38: 52 | H38: Active
A39: EMP043 | B39: John | C39: Wilson | D39: OPS06 | E39: 03-Aug-22 | F39: 111845 | G39: 98 | H39: active
A40: EMP068 | B40: Melissa | C40: Brown | D40: SAL05 | E40: 06/29/2022 | F40: 69219 | G40: 93 | H40: Actv
...

Sheet Lookup_Departments
A1: Dept_Code | B1: Department_Name
A2: HR01 | B2: Human Resources
A3: IT02 | B3: Information Technology
A4: FIN03 | B4: Finance
A5: MKT04 | B5: Marketing
A6: SAL05 | B6: Sales
A7: OPS06 | B7: Operations

Sheet Lookup_Performance
A1: Min_Score | B1: Max_Score | C1: Performance_Band | D1: Bonus_Percentage
A2: 0 | B2: 49 | C2: Needs Improvement | D2: 0
A3: 50 | B3: 69 | C3: Developing | D3: 0.02
A4: 70 | B4: 84 | C4: Achieving | D4: 0.05
A5: 85 | B5: 94 | C5: Exceeding | D5: 0.08
A6: 95 | B6: 100 | C6: Outstanding | D6: 0.12

Sheet HR Analysis
A2: 1. Total Headcount And Department Per Salary
A3: Row Labels | B3: Count of Emp ID | C3: Sum of Salary
A4: Finance | B4: 17 | C4: 1481950.8
A5: Human Resources | B5: 18 | C5: 1539652.9
A6: Information Technology | B6: 36 | C6: 2898461.7
A7: Marketing | B7: 19 | C7: 1622750.9 | H7: =GETPIVOTDATA("Sum of Salary",$A$3) -> 12540590
A8: Operations | B8: 29 | C8: 2321447.9
A9: Sales | B9: 31 | C9: 2676325.4
A10: Grand Total | B10: 150 | C10: 12540590 | D10: =GETPIVOTDATA("Count of Emp ID",$A$3) -> 150
A13: 2. Atrrition Rate By Department
A14: Count of Emp ID | B14: Column Labels
A15: Row Labels | B15: NO | C15: YES | D15: Grand Total
A16: Finance | B16: 0.82352941 | C16: 0.17647059 | D16: 1
A17: Human Resources | B17: 0.83333333 | C17: 0.16666667 | D17: 1
A18: Information Technology | B18: 0.77777778 | C18: 0.22222222 | D18: 1
A19: Marketing | B19: 0.84210526 | C19: 0.15789474 | D19: 1
A20: Operations | B20: 0.62068966 | C20: 0.37931034 | D20: 1
A21: Sales | B21: 0.80645161 | C21: 0.19354839 | D21: 1
A22: Grand Total | B22: 0.77333333 | C22: 0.22666667 | D22: 1 | E22: =GETPIVOTDATA("Emp ID",$A$14,"Attrition Rate","YES") -> 0.22666667
A26: 3. Performance By Status
A27: Row Labels | B27: Average of Perf_Score
A28: ACTIVE | B28: 60.275862
A29: LEFT | B29: 64.363636
A30: active | B30: 70.229885
A31: Left | B31: 67.769231
A32: Resigned | B32: 76.4
A33: Grand Total | B33: 68.073333
A37: 4. Bonus Payout
A38: Row Labels | B38: Sum of Eligible Bonus Amount
A39: Achieving | B39: 165216.93
A40: Developing | B40: 84593.269
A41: Exceeding | B41: 144689.43
A42: Needs Improvement | B42: 0
A43: Outstanding | B43: 92411.512
A44: Grand Total | B44: 486911.14 | C44: =GETPIVOTDATA("Eligible Bonus Amount",$A$38) -> 486911.14

Sheet Pivot Chart

Sheet HR_DASHBOARD

Sheet DB_Formula
A1: Emp ID | B1: First_Name | C1: Last_Name | D1: Dept Code | E1: Dept Code | F1: Department Name | G1: Hire Date | H1: Salary | I1: Perf_Score | J1: Perf_ Band | K1: Employment Status | L1: Employment Status | M1: Year of Service | N1: Bonus Percentage | O1: Eligible Bonus Amount | P1: Attrition Rate
A2: EMP127 | B2: Emily | C2: Brown | D2: IT02 | E2: =UPPER(TRIM(D2)) -> IT02 | F2: =_xlfn.XLOOKUP(E2,Lookup_Departments!A:A,Lookup_Departments!B:B) -> Information Technology | G2: 43093 | H2: 50361 | I2: 52 | J2: =_xlfn.XLOOKUP(I2,Lookup_Performance!A:A, Lookup_Performance!C:C, , -1) -> Developing | K2: active | L2: =UPPER(TRIM(K2)) -> ACTIVE | M2: =DATEDIF(G2, TODAY(), "Y") -> 8 | N2: =_xlfn.XLOOKUP(J:J,Lookup_Performance!C:C,Lookup_Performance!D:D, "Not Found") -> 0.02 | O2: =N2*H2 -> 1007.22 | P2: =IF(OR(ISNUMBER(SEARCH("LEFT",L2)), ISNUMBER(SEARCH("RESIGN", L2))), "YES", "NO") -> NO | Q2: =TRIM(UPPER(L4)) -> LEFT | R2: ="|"&L4&"|" -> |LEFT|
A3: EMP046 | B3: Richard | C3: Hernandez | D3: MKT04 | E3: =UPPER(TRIM(D3)) -> MKT04 | F3: =_xlfn.XLOOKUP(E3,Lookup_Departments!A:A,Lookup_Departments!B:B) -> Marketing | G3: 44659 | H3: 112673 | I3: 68 | J3: =_xlfn.XLOOKUP(I3,Lookup_Performance!A:A, Lookup_Performance!C:C, , -1) -> Developing | K3: ACTIVE | L3: =UPPER(TRIM(K3)) -> ACTIVE | M3: =DATEDIF(G3, TODAY(), "Y") -> 4 | N3: =_xlfn.XLOOKUP(J:J,Lookup_Performance!C:C,Lookup_Performance!D:D, "Not Found") -> 0.02 | O3: =N3*H3 -> 2253.46 | P3: =IF(OR(ISNUMBER(SEARCH("LEFT",L3)), ISNUMBER(SEARCH("RESIGN", L3))), "YES", "NO") -> NO
A4: EMP134 | B4: Emily | C4: Gonzalez | D4: IT02 | E4: =UPPER(TRIM(D4)) -> IT02 | F4: =_xlfn.XLOOKUP(E4,Lookup_Departments!A:A,Lookup_Departments!B:B) -> Information Technology | G4: 42431 | H4: 114425 | I4: 54 | J4: =_xlfn.XLOOKUP(I4,Lookup_Performance!A:A, Lookup_Performance!C:C, , -1) -> Developing | K4: LEFT | L4: =UPPER(TRIM(K4)) -> LEFT | M4: =DATEDIF(G4, TODAY(), "Y") -> 10 | N4: =_xlfn.XLOOKUP(J:J,Lookup_Performance!C:C,Lookup_Performance!D:D, "Not Found") -> 0.02 | O4: =N4*H4 -> 2288.5 | P4: =IF(OR(ISNUMBER(SEARCH("LEFT",L4)), ISNUMBER(SEARCH("RESIGN", L4))), "YES", "NO") -> YES
A5: EMP139 | B5: John | C5: Martinez | D5: FIN03 | E5: =UPPER(TRIM(D5)) -> FIN03 | F5: =_xlfn.XLOOKUP(E5,Lookup_Departments!A:A,Lookup_Departments!B:B) -> Finance | G5: 45110 | H5: 103831 | I5: 70 | J5: =_xlfn.XLOOKUP(I5,Lookup_Performance!A:A, Lookup_Performance!C:C, , -1) -> Achieving | K5: active | L5: =UPPER(TRIM(K5)) -> ACTIVE | M5: =DATEDIF(G5, TODAY(), "Y") -> 3 | N5: =_xlfn.XLOOKUP(J:J,Lookup_Performance!C:C,Lookup_Performance!D:D, "Not Found") -> 0.05 | O5: =N5*H5 -> 5191.55 | P5: =IF(OR(ISNUMBER(SEARCH("LEFT",L5)), ISNUMBER(SEARCH("RESIGN", L5))), "YES", "NO") -> NO
A6: EMP112 | B6: Thomas | C6: Smith | D6: IT02 | E6: =UPPER(TRIM(D6)) -> IT02 | F6: =_xlfn.XLOOKUP(E6,Lookup_Departments!A:A,Lookup_Departments!B:B) -> Information Technology | G6: 44977 | H6: 73785 | I6: 40 | J6: =_xlfn.XLOOKUP(I6,Lookup_Performance!A:A, Lookup_Performance!C:C, , -1) -> Needs Improvement | K6: Left | L6: =UPPER(TRIM(K6)) -> LEFT | M6: =DATEDIF(G6, TODAY(), "Y") -> 3 | N6: =_xlfn.XLOOKUP(J:J,Lookup_Performance!C:C,Lookup_Performance!D:D, "Not Found") -> 0 | O6: =N6*H6 -> 0 | P6: =IF(OR(ISNUMBER(SEARCH("LEFT",L6)), ISNUMBER(SEARCH("RESIGN", L6))), "YES", "NO") -> YES | Q6: =L4="LEFT" -> TRUE
A7: EMP030 | B7: Emily | C7: Johnson | D7: OPS06 | E7: =UPPER(TRIM(D7)) -> OPS06 | F7: =_xlfn.XLOOKUP(E7,Lookup_Departments!A:A,Lookup_Departments!B:B) -> Operations | G7: 43892 | H7: 115882 | I7: 49 | J7: =_xlfn.XLOOKUP(I7,Lookup_Performance!A:A, Lookup_Performance!C:C, , -1) -> Needs Improvement | K7: ACTIVE | L7: =UPPER(TRIM(K7)) -> ACTIVE | M7: =DATEDIF(G7, TODAY(), "Y") -> 6 | N7: =_xlfn.XLOOKUP(J:J,Lookup_Performance!C:C,Lookup_Performance!D:D, "Not Found") -> 0 | O7: =N7*H7 -> 0 | P7: =IF(OR(ISNUMBER(SEARCH("LEFT",L7)), ISNUMBER(SEARCH("RESIGN", L7))), "YES", "NO") -> NO
A8: EMP096 | B8: John | C8: Wilson | D8: OPS06 | E8: =UPPER(TRIM(D8)) -> OPS06 | F8: =_xlfn.XLOOKUP(E8,Lookup_Departments!A:A,Lookup_Departments!B:B) -> Operations | G8: 45272 | H8: 59980 | I8: 70 | J8: =_xlfn.XLOOKUP(I8,Lookup_Performance!A:A, Lookup_Performance!C:C, , -1) -> Achieving | K8: Left | L8: =UPPER(TRIM(K8)) -> LEFT | M8: =DATEDIF(G8, TODAY(), "Y") -> 2 | N8: =_xlfn.XLOOKUP(J:J,Lookup_Performance!C:C,Lookup_Performance!D:D, "Not Found") -> 0.05 | O8: =N8*H8 -> 2999 | P8: =IF(OR(ISNUMBER(SEARCH("LEFT",L8)), ISNUMBER(SEARCH("RESIGN", L8))), "YES", "NO") -> YES
A9: EMP098 | B9: Jessica | C9: Smith | D9: OPS06 | E9: =UPPER(TRIM(D9)) -> OPS06 | F9: =_xlfn.XLOOKUP(E9,Lookup_Departments!A:A,Lookup_Departments!B:B) -> Operations | G9: 44174 | H9: 68728 | I9: 45 | J9: =_xlfn.XLOOKUP(I9,Lookup_Performance!A:A, Lookup_Performance!C:C, , -1) -> Needs Improvement | K9: ACTIVE | L9: =UPPER(TRIM(K9)) -> ACTIVE | M9: =DATEDIF(G9, TODAY(), "Y") -> 5 | N9: =_xlfn.XLOOKUP(J:J,Lookup_Performance!C:C,Lookup_Performance!D:D, "Not Found") -> 0 | O9: =N9*H9 -> 0 | P9: =IF(OR(ISNUMBER(SEARCH("LEFT",L9)), ISNUMBER(SEARCH("RESIGN", L9))), "YES", "NO") -> NO
A10: EMP095 | B10: =B9 -> Jessica | C10: Rodriguez | D10: FIN03 | E10: =UPPER(TRIM(D10)) -> FIN03 | F10: =_xlfn.XLOOKUP(E10,Lookup_Departments!A:A,Lookup_Departments!B:B) -> Finance | G10: 43107 | H10: 102139 | I10: 79 | J10: =_xlfn.XLOOKUP(I10,Lookup_Performance!A:A, Lookup_Performance!C:C, , -1) -> Achieving | K10: active | L10: =UPPER(TRIM(K10)) -> ACTIVE | M10: =DATEDIF(G10, TODAY(), "Y") -> 8 | N10: =_xlfn.XLOOKUP(J:J,Lookup_Performance!C:C,Lookup_Performance!D:D, "Not Found") -> 0.05 | O10: =N10*H10 -> 5106.95 | P10: =IF(OR(ISNUMBER(SEARCH("LEFT",L10)), ISNUMBER(SEARCH("RESIGN", L10))), "YES", "NO") -> NO
A11: EMP140 | B11: Michael | C11: Martinez | D11: SAL05 | E11: =UPPER(TRIM(D11)) -> SAL05 | F11: =_xlfn.XLOOKUP(E11,Lookup_Departments!A:A,Lookup_Departments!B:B) -> Sales | G11: 42676 | H11: 94998 | I11: 58 | J11: =_xlfn.XLOOKUP(I11,Lookup_Performance!A:A, Lookup_Performance!C:C, , -1) -> Developing | K11: Active | L11: =UPPER(TRIM(K11)) -> ACTIVE | M11: =DATEDIF(G11, TODAY(), "Y") -> 9 | N11: =_xlfn.XLOOKUP(J:J,Lookup_Performance!C:C,Lookup_Performance!D:D, "Not Found") -> 0.02 | O11: =N11*H11 -> 1899.96 | P11: =IF(OR(ISNUMBER(SEARCH("LEFT",L11)), ISNUMBER(SEARCH("RESIGN", L11))), "YES", "NO") -> NO | Q11: =LEN(L4) -> 4
A12: EMP020 | B12: Emily | C12: Miller | D12: sal05 | E12: =UPPER(TRIM(D12)) -> SAL05 | F12: =_xlfn.XLOOKUP(E12,Lookup_Departments!A:A,Lookup_Departments!B:B) -> Sales | G12: 43911 | H12: 118635 | I12: 49 | J12: =_xlfn.XLOOKUP(I12,Lookup_Performance!A:A, Lookup_Performance!C:C, , -1) -> Needs Improvement | K12: Active | L12: =UPPER(TRIM(K12)) -> ACTIVE | M12: =DATEDIF(G12, TODAY(), "Y") -> 6 | N12: =_xlfn.XLOOKUP(J:J,Lookup_Performance!C:C,Lookup_Performance!D:D, "Not Found") -> 0 | O12: =N12*H12 -> 0 | P12: =IF(OR(ISNUMBER(SEARCH("LEFT",L12)), ISNUMBER(SEARCH("RESIGN", L12))), "YES", "NO") -> NO
A13: EMP057 | B13: Emily | C13: Hernandez | D13: IT02 | E13: =UPPER(TRIM(D13)) -> IT02 | F13: =_xlfn.XLOOKUP(E13,Lookup_Departments!A:A,Lookup_Departments!B:B) -> Information Technology | G13: 42425 | H13: 76918 | I13: 62 | J13: =_xlfn.XLOOKUP(I13,Lookup_Performance!A:A, Lookup_Performance!C:C, , -1) -> Developing | K13: Active | L13: =UPPER(TRIM(K13)) -> ACTIVE | M13: =DATEDIF(G13, TODAY(), "Y") -> 10 | N13: =_xlfn.XLOOKUP(J:J,Lookup_Performance!C:C,Lookup_Performance!D:D, "Not Found") -> 0.02 | O13: =N13*H13 -> 1538.36 | P13: =IF(OR(ISNUMBER(SEARCH("LEFT",L13)), ISNUMBER(SEARCH("RESIGN", L13))), "YES", "NO") -> NO
A14: EMP016 | B14: Jane | C14: Williams | D14: mkt04 | E14: =UPPER(TRIM(D14)) -> MKT04 | F14: =_xlfn.XLOOKUP(E14,Lookup_Departments!A:A,Lookup_Departments!B:B) -> Marketing | G14: 44364 | H14: 61408 | I14: 48 | J14: =_xlfn.XLOOKUP(I14,Lookup_Performance!A:A, Lookup_Performance!C:C, , -1) -> Needs Improvement | K14: ACTIVE | L14: =UPPER(TRIM(K14)) -> ACTIVE | M14: =DATEDIF(G14, TODAY(), "Y") -> 5 | N14: =_xlfn.XLOOKUP(J:J,Lookup_Performance!C:C,Lookup_Performance!D:D, "Not Found") -> 0 | O14: =N14*H14 -> 0 | P14: =IF(OR(ISNUMBER(SEARCH("LEFT",L14)), ISNUMBER(SEARCH("RESIGN", L14))), "YES", "NO") -> NO
A15: EMP070 | B15: Jane | C15: Miller | D15: MKT04 | E15: =UPPER(TRIM(D15)) -> MKT04 | F15: =_xlfn.XLOOKUP(E15,Lookup_Departments!A:A,Lookup_Departments!B:B) -> Marketing | G15: 44001 | H15: 99990 | I15: 54 | J15: =_xlfn.XLOOKUP(I15,Lookup_Performance!A:A, Lookup_Performance!C:C, , -1) -> Developing | K15: Active | L15: =UPPER(TRIM(K15)) -> ACTIVE | M15: =DATEDIF(G15, TODAY(), "Y") -> 6 | N15: =_xlfn.XLOOKUP(J:J,Lookup_Performance!C:C,Lookup_Performance!D:D, "Not Found") -> 0.02 | O15: =N15*H15 -> 1999.8 | P15: =IF(OR(ISNUMBER(SEARCH("LEFT",L15)), ISNUMBER(SEARCH("RESIGN", L15))), "YES", "NO") -> NO
A16: EMP025 | B16: Robert | C16: Jones | D16: MKT04 | E16: =UPPER(TRIM(D16)) -> MKT04 | F16: =_xlfn.XLOOKUP(E16,Lookup_Departments!A:A,Lookup_Departments!B:B) -> Marketing | G16: 43820 | H16: 80385 | I16: 68 | J16: =_xlfn.XLOOKUP(I16,Lookup_Performance!A:A, Lookup_Performance!C:C, , -1) -> Developing | K16: active | L16: =UPPER(TRIM(K16)) -> ACTIVE | M16: =DATEDIF(G16, TODAY(), "Y") -> 6 | N16: =_xlfn.XLOOKUP(J:J,Lookup_Performance!C:C,Lookup_Performance!D:D, "Not Found") -> 0.02 | O16: =N16*H16 -> 1607.7 | P16: =IF(OR(ISNUMBER(SEARCH("LEFT",L16)), ISNUMBER(SEARCH("RESIGN", L16))), "YES", "NO") -> NO
A17: EMP031 | B17: Thomas | C17: Rodriguez | D17: SAL05 | E17: =UPPER(TRIM(D17)) -> SAL05 | F17: =_xlfn.XLOOKUP(E17,Lookup_Departments!A:A,Lookup_Departments!B:B) -> Sales | G17: 45169 | H17: 65290 | I17: 77 | J17: =_xlfn.XLOOKUP(I17,Lookup_Performance!A:A, Lookup_Performance!C:C, , -1) -> Achieving | K17: active | L17: =UPPER(TRIM(K17)) -> ACTIVE | M17: =DATEDIF(G17, TODAY(), "Y") -> 2 | N17: =_xlfn.XLOOKUP(J:J,Lookup_Performance!C:C,Lookup_Performance!D:D, "Not Found") -> 0.05 | O17: =N17*H17 -> 3264.5 | P17: =IF(OR(ISNUMBER(SEARCH("LEFT",L17)), ISNUMBER(SEARCH("RESIGN", L17))), "YES", "NO") -> NO
A18: EMP126 | B18: Emily | C18: Davis | D18: IT02 | E18: =UPPER(TRIM(D18)) -> IT02 | F18: =_xlfn.XLOOKUP(E18,Lookup_Departments!A:A,Lookup_Departments!B:B) -> Information Technology | G18: 42337 | H18: 105765 | I18: 42 | J18: =_xlfn.XLOOKUP(I18,Lookup_Performance!A:A, Lookup_Performance!C:C, , -1) -> Needs Improvement | K18: Active | L18: =UPPER(TRIM(K18)) -> ACTIVE | M18: =DATEDIF(G18, TODAY(), "Y") -> 10 | N18: =_xlfn.XLOOKUP(J:J,Lookup_Performance!C:C,Lookup_Performance!D:D, "Not Found") -> 0 | O18: =N18*H18 -> 0 | P18: =IF(OR(ISNUMBER(SEARCH("LEFT",L18)), ISNUMBER(SEARCH("RESIGN", L18))), "YES", "NO") -> NO
A19: EMP109 | B19: James | C19: Martinez | D19: SAL05 | E19: =UPPER(TRIM(D19)) -> SAL05 | F19: =_xlfn.XLOOKUP(E19,Lookup_Departments!A:A,Lookup_Departments!B:B) -> Sales | G19: 42899 | H19: 102921 | I19: 49 | J19: =_xlfn.XLOOKUP(I19,Lookup_Performance!A:A, Lookup_Performance!C:C, , -1) -> Needs Improvement | K19: ACTIVE | L19: =UPPER(TRIM(K19)) -> ACTIVE | M19: =DATEDIF(G19, TODAY(), "Y") -> 9 | N19: =_xlfn.XLOOKUP(J:J,Lookup_Performance!C:C,Lookup_Performance!D:D, "Not Found") -> 0 | O19: =N19*H19 -> 0 | P19: =IF(OR(ISNUMBER(SEARCH("LEFT",L19)), ISNUMBER(SEARCH("RESIGN", L19))), "YES", "NO") -> NO
A20: EMP066 | B20: Emily | C20: Lopez | D20: MKT04 | E20: =UPPER(TRIM(D20)) -> MKT04 | F20: =_xlfn.XLOOKUP(E20,Lookup_Departments!A:A,Lookup_Departments!B:B) -> Marketing | G20: 43235 | H20: 73984 | I20: 93 | J20: =_xlfn.XLOOKUP(I20,Lookup_Performance!A:A, Lookup_Performance!C:C, , -1) -> Exceeding | K20: Active | L20: =UPPER(TRIM(K20)) -> ACTIVE | M20: =DATEDIF(G20, TODAY(), "Y") -> 8 | N20: =_xlfn.XLOOKUP(J:J,Lookup_Performance!C:C,Lookup_Performance!D:D, "Not Found") -> 0.08 | O20: =N20*H20 -> 5918.72 | P20: =IF(OR(ISNUMBER(SEARCH("LEFT",L20)), ISNUMBER(SEARCH("RESIGN", L20))), "YES", "NO") -> NO
A21: EMP120 | B21: Ashley | C21: Gonzalez | D21: IT02 | E21: =UPPER(TRIM(D21)) -> IT02 | F21: =_xlfn.XLOOKUP(E21,Lookup_Departments!A:A,Lookup_Departments!B:B) -> Information Technology | G21: 42575 | H21: 83603.93 | I21: 75 | J21: =_xlfn.XLOOKUP(I21,Lookup_Performance!A:A, Lookup_Performance!C:C, , -1) -> Achieving | K21: Active | L21: =UPPER(TRIM(K21)) -> ACTIVE | M21: =DATEDIF(G21, TODAY(), "Y") -> 9 | N21: =_xlfn.XLOOKUP(J:J,Lookup_Performance!C:C,Lookup_Performance!D:D, "Not Found") -> 0.05 | O21: =N21*H21 -> 4180.1965 | P21: =IF(OR(ISNUMBER(SEARCH("LEFT",L21)), ISNUMBER(SEARCH("RESIGN", L21))), "YES", "NO") -> NO
A22: EMP019 | B22: Amanda | C22: Hernandez | D22: FIN03 | E22: =UPPER(TRIM(D22)) -> FIN03 | F22: =_xlfn.XLOOKUP(E22,Lookup_Departments!A:A,Lookup_Departments!B:B) -> Finance | G22: 43076 | H22: 118527 | I22: 50 | J22: =_xlfn.XLOOKUP(I22,Lookup_Performance!A:A, Lookup_Performance!C:C, , -1) -> Developing | K22: Active | L22: =UPPER(TRIM(K22)) -> ACTIVE | M22: =DATEDIF(G22, TODAY(), "Y") -> 8 | N22: =_xlfn.XLOOKUP(J:J,Lookup_Performance!C:C,Lookup_Performance!D:D, "Not Found") -> 0.02 | O22: =N22*H22 -> 2370.54 | P22: =IF(OR(ISNUMBER(SEARCH("LEFT",L22)), ISNUMBER(SEARCH("RESIGN", L22))), "YES", "NO") -> NO
A23: EMP013 | B23: Michael | C23: Hernandez | D23: MKT04 | E23: =UPPER(TRIM(D23)) -> MKT04 | F23: =_xlfn.XLOOKUP(E23,Lookup_Departments!A:A,Lookup_Departments!B:B) -> Marketing | G23: 44353 | H23: 107871 | I23: 88 | J23: =_xlfn.XLOOKUP(I23,Lookup_Performance!A:A, Lookup_Performance!C:C, , -1) -> Exceeding | K23: active | L23: =UPPER(TRIM(K23)) -> ACTIVE | M23: =DATEDIF(G23, TODAY(), "Y") -> 5 | N23: =_xlfn.XLOOKUP(J:J,Lookup_Performance!C:C,Lookup_Performance!D:D, "Not Found") -> 0.08 | O23: =N23*H23 -> 8629.68 | P23: =IF(OR(ISNUMBER(SEARCH("LEFT",L23)), ISNUMBER(SEARCH("RESIGN", L23))), "YES", "NO") -> NO
... A27: EMP052 | B27: Ashley | C27: Williams | D27: SAL05 | E27: =UPPER(TRIM(D27)) -> SAL05 | F27: =_xlfn.XLOOKUP(E27,Lookup_Departments!A:A,Lookup_Departments!B:B) -> Sales | G27: 45134 | H27: 81205 | I27: 59 | J27: =_xlfn.XLOOKUP(I27,Lookup_Performance!A:A, Lookup_Performance!C:C, , -1) -> Developing | K27: Active | L27: =UPPER(TRIM(K27)) -> ACTIVE | M27: =DATEDIF(G27, TODAY(), "Y") -> 2 | N27: =_xlfn.XLOOKUP(J:J,Lookup_Performance!C:C,Lookup_Performance!D:D, "Not Found") -> 0.02 | O27: =N27*H27 -> 1624.1 | P27: =IF(OR(ISNUMBER(SEARCH("LEFT",L27)), ISNUMBER(SEARCH("RESIGN", L27))), "YES", "NO") -> NO
A28: EMP129 | B28: =B27 -> Ashley | C28: Wilson | D28: SAL05 | E28: =UPPER(TRIM(D28)) -> SAL05 | F28: =_xlfn.XLOOKUP(E28,Lookup_Departments!A:A,Lookup_Departments!B:B) -> Sales | G28: 43732 | H28: 77610 | I28: 88 | J28: =_xlfn.XLOOKUP(I28,Lookup_Performance!A:A, Lookup_Performance!C:C, , -1) -> Exceeding | K28: Active | L28: =UPPER(TRIM(K28)) -> ACTIVE | M28: =DATEDIF(G28, TODAY(), "Y") -> 6 | N28: =_xlfn.XLOOKUP(J:J,Lookup_Performance!C:C,Lookup_Performance!D:D, "Not Found") -> 0.08 | O28: =N28*H28 -> 6208.8 | P28: =IF(OR(ISNUMBER(SEARCH("LEFT",L28)), ISNUMBER(SEARCH("RESIGN", L28))), "YES", "NO") -> NO
A29: EMP146 | B29: John | C29: Rodriguez | D29: it02 | E29: =UPPER(TRIM(D29)) -> IT02 | F29: =_xlfn.XLOOKUP(E29,Lookup_Departments!A:A,Lookup_Departments!B:B) -> Information Technology | G29: 44765 | H29: 50873 | I29: 90 | J29: =_xlfn.XLOOKUP(I29,Lookup_Performance!A:A, Lookup_Performance!C:C, , -1) -> Exceeding | K29: Active | L29: =UPPER(TRIM(K29)) -> ACTIVE | M29: =DATEDIF(G29, TODAY(), "Y") -> 3 | N29: =_xlfn.XLOOKUP(J:J,Lookup_Performance!C:C,Lookup_Performance!D:D, "Not Found") -> 0.08 | O29: =N29*H29 -> 4069.84 | P29: =IF(OR(ISNUMBER(SEARCH("LEFT",L29)), ISNUMBER(SEARCH("RESIGN", L29))), "YES", "NO") -> NO
A30: EMP099 | B30: Thomas | C30: Wilson | D30: fin03 | E30: =UPPER(TRIM(D30)) -> FIN03 | F30: =_xlfn.XLOOKUP(E30,Lookup_Departments!A:A,Lookup_Departments!B:B) -> Finance | G30: 43233 | H30: 85312 | I30: 66 | J30: =_xlfn.XLOOKUP(I30,Lookup_Performance!A:A, Lookup_Performance!C:C, , -1) -> Developing | K30: active | L30: =UPPER(TRIM(K30)) -> ACTIVE | M30: =DATEDIF(G30, TODAY(), "Y") -> 8 | N30: =_xlfn.XLOOKUP(J:J,Lookup_Performance!C:C,Lookup_Performance!D:D, "Not Found") -> 0.02 | O30: =N30*H30 -> 1706.24 | P30: =IF(OR(ISNUMBER(SEARCH("LEFT",L30)), ISNUMBER(SEARCH("RESIGN", L30))), "YES", "NO") -> NO
A31: EMP015 | B31: Michael | C31: Rodriguez | D31: SAL05 | E31: =UPPER(TRIM(D31)) -> SAL05 | F31: =_xlfn.XLOOKUP(E31,Lookup_Departments!A:A,Lookup_Departments!B:B) -> Sales | G31: 42202 | H31: 83603.93 | I31: 68 | J31: =_xlfn.XLOOKUP(I31,Lookup_Performance!A:A, Lookup_Performance!C:C, , -1) -> Developing | K31: active | L31: =UPPER(TRIM(K31)) -> ACTIVE | M31: =DATEDIF(G31, TODAY(), "Y") -> 10 | N31: =_xlfn.XLOOKUP(J:J,Lookup_Performance!C:C,Lookup_Performance!D:D, "Not Found") -> 0.02 | O31: =N31*H31 -> 1672.0786 | P31: =IF(OR(ISNUMBER(SEARCH("LEFT",L31)), ISNUMBER(SEARCH("RESIGN", L31))), "YES", "NO") -> NO
A32: EMP076 | B32: John | C32: Hernandez | D32: OPS06 | E32: =UPPER(TRIM(D32)) -> OPS06 | F32: =_xlfn.XLOOKUP(E32,Lookup_Departments!A:A,Lookup_Departments!B:B) -> Operations | G32: 42221 | H32: 97055 | I32: 80 | J32: =_xlfn.XLOOKUP(I32,Lookup_Performance!A:A, Lookup_Performance!C:C, , -1) -> Achieving | K32: Active | L32: =UPPER(TRIM(K32)) -> ACTIVE | M32: =DATEDIF(G32, TODAY(), "Y") -> 10 | N32: =_xlfn.XLOOKUP(J:J,Lookup_Performance!C:C,Lookup_Performance!D:D, "Not Found") -> 0.05 | O32: =N32*H32 -> 4852.75 | P32: =IF(OR(ISNUMBER(SEARCH("LEFT",L32)), ISNUMBER(SEARCH("RESIGN", L32))), "YES", "NO") -> NO
A33: EMP137 | B33: Thomas | C33: Johnson | D33: IT02 | E33: =UPPER(TRIM(D33)) -> IT02 | F33: =_xlfn.XLOOKUP(E33,Lookup_Departments!A:A,Lookup_Departments!B:B) -> Information Technology | G33: 45195 | H33: 66069 | I33: 72 | J33: =_xlfn.XLOOKUP(I33,Lookup_Performance!A:A, Lookup_Performance!C:C, , -1) -> Achieving | K33: Active | L33: =UPPER(TRIM(K33)) -> ACTIVE | M33: =DATEDIF(G33, TODAY(), "Y") -> 2 | N33: =_xlfn.XLOOKUP(J:J,Lookup_Performance!C:C,Lookup_Performance!D:D, "Not Found") -> 0.05 | O33: =N33*H33 -> 3303.45 | P33: =IF(OR(ISNUMBER(SEARCH("LEFT",L33)), ISNUMBER(SEARCH("RESIGN", L33))), "YES", "NO") -> NO
A34: EMP056 | B34: Michael | C34: Brown | D34: it02 | E34: =UPPER(TRIM(D34)) -> IT02 | F34: =_xlfn.XLOOKUP(E34,Lookup_Departments!A:A,Lookup_Departments!B:B) -> Information Technology | G34: 43626 | H34: 90157 | I34: 58 | J34: =_xlfn.XLOOKUP(I34,Lookup_Performance!A:A, Lookup_Performance!C:C, , -1) -> Developing | K34: active | L34: =UPPER(TRIM(K34)) -> ACTIVE | M34: =DATEDIF(G34, TODAY(), "Y") -> 7 | N34: =_xlfn.XLOOKUP(J:J,Lookup_Performance!C:C,Lookup_Performance!D:D, "Not Found") -> 0.02 | O34: =N34*H34 -> 1803.14 | P34: =IF(OR(ISNUMBER(SEARCH("LEFT",L34)), ISNUMBER(SEARCH("RESIGN", L34))), "YES", "NO") -> NO
A35: EMP125 | B35: Sarah | C35: Martinez | D35: HR01 | E35: =UPPER(TRIM(D35)) -> HR01 | F35: =_xlfn.XLOOKUP(E35,Lookup_Departments!A:A,Lookup_Departments!B:B) -> Human Resources | G35: 44578 | H35: 59899 | I35: 78 | J35: =_xlfn.XLOOKUP(I35,Lookup_Performance!A:A, Lookup_Performance!C:C, , -1) -> Achieving | K35: Active | L35: =UPPER(TRIM(K35)) -> ACTIVE | M35: =DATEDIF(G35, TODAY(), "Y") -> 4 | N35: =_xlfn.XLOOKUP(J:J,Lookup_Performance!C:C,Lookup_Performance!D:D, "Not Found") -> 0.05 | O35: =N35*H35 -> 2994.95 | P35: =IF(OR(ISNUMBER(SEARCH("LEFT",L35)), ISNUMBER(SEARCH("RESIGN", L35))), "YES", "NO") -> NO
A36: EMP085 | B36: Jane | C36: Jones | D36: FIN03 | E36: =UPPER(TRIM(D36)) -> FIN03 | F36: =_xlfn.XLOOKUP(E36,Lookup_Departments!A:A,Lookup_Departments!B:B) -> Finance | G36: 42919 | H36: 113389 | I36: 30 | J36: =_xlfn.XLOOKUP(I36,Lookup_Performance!A:A, Lookup_Performance!C:C, , -1) -> Needs Improvement | K36: ACTIVE | L36: =UPPER(TRIM(K36)) -> ACTIVE | M36: =DATEDIF(G36, TODAY(), "Y") -> 9 | N36: =_xlfn.XLOOKUP(J:J,Lookup_Performance!C:C,Lookup_Performance!D:D, "Not Found") -> 0 | O36: =N36*H36 -> 0 | P36: =IF(OR(ISNUMBER(SEARCH("LEFT",L36)), ISNUMBER(SEARCH("RESIGN", L36))), "YES", "NO") -> NO
A37: EMP106 | B37: Emily | C37: Brown | D37: IT02 | E37: =UPPER(TRIM(D37)) -> IT02 | F37: =_xlfn.XLOOKUP(E37,Lookup_Departments!A:A,Lookup_Departments!B:B) -> Information Technology | G37: 42248 | H37: 102691 | I37: 52 | J37: =_xlfn.XLOOKUP(I37,Lookup_Performance!A:A, Lookup_Performance!C:C, , -1) -> Developing | K37: Active | L37: =UPPER(TRIM(K37)) -> ACTIVE | M37: =DATEDIF(G37, TODAY(), "Y") -> 10 | N37: =_xlfn.XLOOKUP(J:J,Lookup_Performance!C:C,Lookup_Performance!D:D, "Not Found") -> 0.02 | O37: =N37*H37 -> 2053.82 | P37: =IF(OR(ISNUMBER(SEARCH("LEFT",L37)), ISNUMBER(SEARCH("RESIGN", L37))), "YES", "NO") -> NO
A38: EMP043 | B38: =B37 -> Emily | C38: Wilson | D38: OPS06 | E38: =UPPER(TRIM(D38)) -> OPS06 | F38: =_xlfn.XLOOKUP(E38,Lookup_Departments!A:A,Lookup_Departments!B:B) -> Operations | G38: 44776 | H38: 111845 | I38: 98 | J38: =_xlfn.XLOOKUP(I38,Lookup_Performance!A:A, Lookup_Performance!C:C, , -1) -> Outstanding | K38: active | L38: =UPPER(TRIM(K38)) -> ACTIVE | M38: =DATEDIF(G38, TODAY(), "Y") -> 3 | N38: =_xlfn.XLOOKUP(J:J,Lookup_Performance!C:C,Lookup_Performance!D:D, "Not Found") -> 0.12 | O38: =N38*H38 -> 13421.4 | P38: =IF(OR(ISNUMBER(SEARCH("LEFT",L38)), ISNUMBER(SEARCH("RESIGN", L38))), "YES", "NO") -> NO
A39: EMP068 | B39: John | C39: Brown | D39: SAL05 | E39: =UPPER(TRIM(D39)) -> SAL05 | F39: =_xlfn.XLOOKUP(E39,Lookup_Departments!A:A,Lookup_Departments!B:B) -> Sales | G39: 44741 | H39: 69219 | I39: 93 | J39: =_xlfn.XLOOKUP(I39,Lookup_Performance!A:A, Lookup_Performance!C:C, , -1) -> Exceeding | K39: Active | L39: =UPPER(TRIM(K39)) -> ACTIVE | M39: =DATEDIF(G39, TODAY(), "Y") -> 4 | N39: =_xlfn.XLOOKUP(J:J,Lookup_Performance!C:C,Lookup_Performance!D:D, "Not Found") -> 0.08 | O39: =N39*H39 -> 5537.52 | P39: =IF(OR(ISNUMBER(SEARCH("LEFT",L39)), ISNUMBER(SEARCH("RESIGN", L39))), "YES", "NO") -> NO
A40: EMP128 | B40: Melissa | C40: Smith | D40: FIN03 | E40: =UPPER(TRIM(D40)) -> FIN03 | F40: =_xlfn.XLOOKUP(E40,Lookup_Departments!A:A,Lookup_Departments!B:B) -> Finance | G40: 43949 | H40: 83603.93 | I40: 80 | J40: =_xlfn.XLOOKUP(I40,Lookup_Performance!A:A, Lookup_Performance!C:C, , -1) -> Achieving | K40: left | L40: =UPPER(TRIM(K40)) -> LEFT | M40: =DATEDIF(G40, TODAY(), "Y") -> 6 | N40: =_xlfn.XLOOKUP(J:J,Lookup_Performance!C:C,Lookup_Performance!D:D, "Not Found") -> 0.05 | O40: =N40*H40 -> 4180.1965 | P40: =IF(OR(ISNUMBER(SEARCH("LEFT",L40)), ISNUMBER(SEARCH("RESIGN", L40))), "YES", "NO") -> YES
A41: EMP027 | B41: Michael | C41: Miller | D41: OPS06 | E41: =UPPER(TRIM(D41)) -> OPS06 | F41: =_xlfn.XLOOKUP(E41,Lookup_Departments!A:A,Lookup_Departments!B:B) -> Operations | G41: 42987 | H41: 57514 | I41: 68 | J41: =_xlfn.XLOOKUP(I41,Lookup_Performance!A:A, Lookup_Performance!C:C, , -1) -> Developing | K41: active | L41: =UPPER(TRIM(K41)) -> ACTIVE | M41: =DATEDIF(G41, TODAY(), "Y") -> 8 | N41: =_xlfn.XLOOKUP(J:J,Lookup_Performance!C:C,Lookup_Performance!D:D, "Not Found") -> 0.02 | O41: =N41*H41 -> 1150.28 | P41: =IF(OR(ISNUMBER(SEARCH("LEFT",L41)), ISNUMBER(SEARCH("RESIGN", L41))), "YES", "NO") -> NO
A42: EMP136 | B42: Sarah | C42: Wilson | D42: SAL05 | E42: =UPPER(TRIM(D42)) -> SAL05 | F42: =_xlfn.XLOOKUP(E42,Lookup_Departments!A:A,Lookup_Departments!B:B) -> Sales | G42: 43181 | H42: 86245 | I42: 71 | J42: =_xlfn.XLOOKUP(I42,Lookup_Performance!A:A, Lookup_Performance!C:C, , -1) -> Achieving | K42: LEFT | L42: =UPPER(TRIM(K42)) -> LEFT | M42: =DATEDIF(G42, TODAY(), "Y") -> 8 | N42: =_xlfn.XLOOKUP(J:J,Lookup_Performance!C:C,Lookup_Performance!D:D, "Not Found") -> 0.05 | O42: =N42*H42 -> 4312.25 | P42: =IF(OR(ISNUMBER(SEARCH("LEFT",L42)), ISNUMBER(SEARCH("RESIGN", L42))), "YES", "NO") -> YES
A43: EMP079 | B43: Emily | C43: Hernandez | D43: SAL05 | E43: =UPPER(TRIM(D43)) -> SAL05 | F43: =_xlfn.XLOOKUP(E43,Lookup_Departments!A:A,Lookup_Departments!B:B) -> Sales | G43: 43958 | H43: 52407 | I43: 55 | J43: =_xlfn.XLOOKUP(I43,Lookup_Performance!A:A, Lookup_Performance!C:C, , -1) -> Developing | K43: active | L43: =UPPER(TRIM(K43)) -> ACTIVE | M43: =DATEDIF(G43, TODAY(), "Y") -> 6 | N43: =_xlfn.XLOOKUP(J:J,Lookup_Performance!C:C,Lookup_Performance!D:D, "Not Found") -> 0.02 | O43: =N43*H43 -> 1048.14 | P43: =IF(OR(ISNUMBER(SEARCH("LEFT",L43)), ISNUMBER(SEARCH("RESIGN", L43))), "YES", "NO") -> NO
...
